Workbook

Sheet Etiqueta provisional
J1: Activo | K1: Etiqueta | L1: Seccion
J2: 103015 | K2: =VLOOKUP(J2,Hoja1!A:B,2,0) -> SACABOCADO MILWAUKEE M18 LOGIC 10T | L2: =+_xlfn.XLOOKUP(J2,Hoja1!$A:$A,Hoja1!$C:$C,"") -> B1, N1 M1_WTC
J3: 101483 | K3: =VLOOKUP(J3,Hoja1!A:B,2,0) -> MAQUINA DE CORTE DE NULEO MTM 1CN008 | L3: =+_xlfn.XLOOKUP(J3,Hoja1!$A:$A,Hoja1!$C:$C,"") -> B1, N1_WTC
J4: 101498 | K4: =VLOOKUP(J4,Hoja1!A:B,2,0) -> BOBINADORA ALTA TENSION RESINA (PE011) | L4: =+_xlfn.XLOOKUP(J4,Hoja1!$A:$A,Hoja1!$C:$C,"") -> B1, N1_WTC
J5: 101683 | K5: =VLOOKUP(J5,Hoja1!A:B,2,0) -> MAQUINA DE CORTE DE NUCLEO MTM 2 CN010 | L5: =+_xlfn.XLOOKUP(J5,Hoja1!$A:$A,Hoja1!$C:$C,"") -> B1, N1_WTC
J6: 101689 | K6: =VLOOKUP(J6,Hoja1!A:B,2,0) -> MAQUINA ROSCADORA DE TUBERIA | L6: =+_xlfn.XLOOKUP(J6,Hoja1!$A:$A,Hoja1!$C:$C,"") -> B1, N1_WTC
J7: 101701 | K7: =VLOOKUP(J7,Hoja1!A:B,2,0) -> BASCULA PARA CORTE HORNO | L7: =+_xlfn.XLOOKUP(J7,Hoja1!$A:$A,Hoja1!$C:$C,"") -> B1, N1_WTC
J8: 102270 | K8: =VLOOKUP(J8,Hoja1!A:B,2,0) -> POLIPASTO DE 3 TON CORTE NAVE 1 ATRAS | L8: =+_xlfn.XLOOKUP(J8,Hoja1!$A:$A,Hoja1!$C:$C,"") -> B1, N1_WTC
J9: 102272 | K9: =VLOOKUP(J9,Hoja1!A:B,2,0) -> PUENTE GRUA 5TON BODEGA 1 NAVE 1 ADEL GN016 | L9: =+_xlfn.XLOOKUP(J9,Hoja1!$A:$A,Hoja1!$C:$C,"") -> B1, N1_WTC
J10: 900000000019 | K10: =VLOOKUP(J10,Hoja1!A:B,2,0) -> FABRICACION DISPOSITIVO DE CARGUE | L10: =+_xlfn.XLOOKUP(J10,Hoja1!$A:$A,Hoja1!$C:$C,"") -> B1, N1_WTC
J11: 101465 | K11: =VLOOKUP(J11,Hoja1!A:B,2,0) -> DOBLADORA HIDRAULICA (EN079) | L11: =+_xlfn.XLOOKUP(J11,Hoja1!$A:$A,Hoja1!$C:$C,"") -> B1, N2, M2_WTC
J12: 102256 | K12: =VLOOKUP(J12,Hoja1!A:B,2,0) -> TALADRO DE BANCO TOTECH REF 45E CON CAJA DE PIÑON | L12: =+_xlfn.XLOOKUP(J12,Hoja1!$A:$A,Hoja1!$C:$C,"") -> B1, N2, M2_WTC
K13: =+_xlfn.XLOOKUP(J13,Hoja1!$A:$A,Hoja1!$B:$B,"") -> 0 | L13: =+_xlfn.XLOOKUP(J13,Hoja1!$A:$A,Hoja1!$C:$C,"") -> 0
K14: =+_xlfn.XLOOKUP(J14,Hoja1!$A:$A,Hoja1!$B:$B,"") -> 0 | L14: =+_xlfn.XLOOKUP(J14,Hoja1!$A:$A,Hoja1!$C:$C,"") -> 0
K15: =+_xlfn.XLOOKUP(J15,Hoja1!$A:$A,Hoja1!$B:$B,"") -> 0 | L15: =+_xlfn.XLOOKUP(J15,Hoja1!$A:$A,Hoja1!$C:$C,"") -> 0
K16: =+_xlfn.XLOOKUP(J16,Hoja1!$A:$A,Hoja1!$B:$B,"") -> 0 | L16: =+_xlfn.XLOOKUP(J16,Hoja1!$A:$A,Hoja1!$C:$C,"") -> 0
K17: =+_xlfn.XLOOKUP(J17,Hoja1!$A:$A,Hoja1!$B:$B,"") -> 0 | L17: =+_xlfn.XLOOKUP(J17,Hoja1!$A:$A,Hoja1!$C:$C,"") -> 0
K18: =+_xlfn.XLOOKUP(J18,Hoja1!$A:$A,Hoja1!$B:$B,"") -> 0 | L18: =+_xlfn.XLOOKUP(J18,Hoja1!$A:$A,Hoja1!$C:$C,"") -> 0
K19: =+_xlfn.XLOOKUP(J19,Hoja1!$A:$A,Hoja1!$B:$B,"") -> 0 | L19: =+_xlfn.XLOOKUP(J19,Hoja1!$A:$A,Hoja1!$C:$C,"") -> 0
K20: =+_xlfn.XLOOKUP(J20,Hoja1!$A:$A,Hoja1!$B:$B,"") -> 0 | L20: =+_xlfn.XLOOKUP(J20,Hoja1!$A:$A,Hoja1!$C:$C,"") -> 0
K21: =+_xlfn.XLOOKUP(J21,Hoja1!$A:$A,Hoja1!$B:$B,"") -> 0 | L21: =+_xlfn.XLOOKUP(J21,Hoja1!$A:$A,Hoja1!$C:$C,"") -> 0
K22: =+_xlfn.XLOOKUP(J22,Hoja1!$A:$A,Hoja1!$B:$B,"") -> 0 | L22: =+_xlfn.XLOOKUP(J22,Hoja1!$A:$A,Hoja1!$C:$C,"") -> 0
K23: =+_xlfn.XLOOKUP(J23,Hoja1!$A:$A,Hoja1!$B:$B,"") -> 0 | L23: =+_xlfn.XLOOKUP(J23,Hoja1!$A:$A,Hoja1!$C:$C,"") -> 0
K24: =+_xlfn.XLOOKUP(J24,Hoja1!$A:$A,Hoja1!$B:$B,"") -> 0 | L24: =+_xlfn.XLOOKUP(J24,Hoja1!$A:$A,Hoja1!$C:$C,"") -> 0
... K28: =+_xlfn.XLOOKUP(J28,Hoja1!$A:$A,Hoja1!$B:$B,"") -> 0 | L28: =+_xlfn.XLOOKUP(J28,Hoja1!$A:$A,Hoja1!$C:$C,"") -> 0

Sheet Hoja1
A1: Activo fijo | B1: Denominación del activo fijo | C1: Seccion
A2: 101478 | B2: SISTEMA DE AIRE ACONDIONADO MARCA MCQUAY (GN063) | C2: Administracion_WTC
A3: 101517 | B3: AIRE ACONDICIONADO LG VM242C7 AL004 | C3: Administracion_WTC
A4: 101523 | B4: AIRE ACONDICIONADO MARCA LG (GN037) | C4: Administracion_WTC
A5: 101978 | B5: ARON S.A.S | C5: Administracion_WTC
A6: 101979 | B6: MPS MAYORISTA DE COLOMBIA S.A. | C6: Administracion_WTC
A7: 101991 | B7: SUPERIOR RECTA ESCRITORIO | C7: Administracion_WTC
A8: 102003 | B8: ARCHIVADOR METALICO 2 PUERTAS | C8: Administracion_WTC
A9: 102004 | B9: ESCRITORIO RECTA EN MADERA BASE METALICA | C9: Administracion_WTC
A10: 102005 | B10: 1 ARCHIVADOR CON 3 CAJONERAS Y 1 RECTA EN MADERA B | C10: Administracion_WTC
A11: 102006 | B11: 1 ARCHIVADOR CON 3 CAJONERAS Y 1 RECTA EN MADERA B | C11: Administracion_WTC
A12: 102007 | B12: ARCHIVADOR METALICO 3 MODULOS ESCRITORIO EN MADERA | C12: Administracion_WTC
... A305: 103184 | B305: MAQUINA BOBINADORA 5 HP MOTOR COAXIAL | C305: B2, N1, M4_WTC
A306: 103003 | B306: PUENTE GRUA 5 TON HYUNDAI GN021 | C306: B2, N1_WTC
A307: 102275 | B307: BOBINADORA BROOMFIEL 500 A | C307: B2, N1_WTC
A308: 102280 | B308: BOBINADORA BROOMFIELD 600 (BN018) | C308: B2, N1_WTC
A309: 102282 | B309: HORNO DE CURADO PREMAC 2 IM003 | C309: B2, N1_WTC
A310: 102286 | B310: BOBINADORA BROOMFIELD 600 A | C310: B2, N1_WTC
A311: 102291 | B311: PUENTE GRUA 3 TON BOD. 2 NAVE 1 ATRÁS GN043 | C311: B2, N1_WTC
A312: 102981 | B312: PRENSADORA HIDRAULICA 8 CILINDROS CAP 5TON 2500PSI | C312: B2, N1_WTC
A313: 103182 | B313: BOBINADORA AT-BTXDE 3T 100RPM | C313: B2, N1_WTC
A314: 103233 | B314: PAPERBOARD CYLINDER ROLLING MACHINE MODE | C314: B2, N1_WTC
A315: 102757 | B315: EXTRACTOR DE POLVO HOLY TEK 2 SALIDAS 2HP | C315: B2, N2, M3_WTC
A316: 102920 | B316: SIERRA COLILLADORA INGLETEADORA 12" DEWALT DWS715 | C316: B2, N2, M3_WTC
A317: 102943 | B317: SIERRA COLILLADORA INGLETEADORA 12" DEWALT DWS715 | C317: B2, N2, M3_WTC
A318: 102247 | B318: CIZALLA CORTE MANUAL TIPO KGM1015 SERIAL2010 BN021 | C318: B2, N2, M4_WTC
... A671: 102936 | B671: LAPTOP DELL LATITUDE 3420 8GB RAM | C671: Ventas - WDS - Cota_WTC

Sheet Hoja3
A3: Activo fijo | B3: Denominación del activo fijo | C3: Seccion
A4: 102826 | B4: RETROFITTING CABINA DE PINTURA TANQUES CH055 | C4: B4, N1_WTC
A5: 103003 | B5: PUENTE GRUA 5 TON HYUNDAI GN021 | C5: B2, N1_WTC
A6: 101464 | B6: IMPRESORA MULTIFUNCIONAL LEXMARK MX421 | C6: Almacén_WTC
A7: 101465 | B7: DOBLADORA HIDRAULICA (EN079) | C7: B1, N2, M2_WTC
A8: 101466 | B8: ULTRAMAX II 695 PRO AIRLESS | C8: B4, N1_WTC
A9: 101467 | B9: CONSOLA DE IMPULSO SERIE HV 2013 - OJO 01728 EQUIP | C9: Pruebas_WTC
A10: 101468 | B10: PUENTE GRUA 20 TONELADAS MARCA HYUNDAI (GN017) | C10: B1, N4_WTC
A11: 101470 | B11: BASCULA DIGITAL 20 TONELADAS MARCA LEXUS - REF FOX | C11: B1, N4_WTC
A12: 101472 | B12: MONTACARGA DE 3 TONELADAS MARCA NISSAN REF MI05150 | C12: Almacén_WTC
A13: 101478 | B13: SISTEMA DE AIRE ACONDIONADO MARCA MCQUAY (GN063) | C13: Administracion_WTC
A14: 101479 | B14: EQUIPO DE AIRE ACONDICIONADO MARCA LG INVERTER V - | C14: Almacén_WTC
A15: 101480 | B15: SISTEMA DE AIRE ACONDIONADO MARCA MCQUAY (GN862) | C15: Almacén_WTC
A16: 101481 | B16: COMPUTADOR MARCA DELL LATITUDE 3591 SERIE 51D99S2 | C16: Almacén_WTC
A17: 101482 | B17: ESTIBADORA AZUL MARCA HU-LIF 3000 KG SERIAL 16115 | C17: Almacén_WTC
A18: 101483 | B18: ACTUALIZACION SISTEMA OPERATIVO MTM | C18: B1, N1_WTC
B19: MAQUINA DE CORTE DE NULEO MTM 1CN008 | C19: B1, N1_WTC
B20: RETROFITTING MAQ CORTE NUCLEO MICRO TOOL | C20: B1, N1_WTC
A21: 101484 | B21: PUENTE GRUA 500 KG | C21: B5, N2_WTC
A22: 101485 | B22: BOBINADORA DE BAJA TENSION DIGMOTOR (PE 010) | C22: B2, N2_WTC
A23: 101486 | B23: SOLDADOR MARCA SOLTRONIC REF 0292274 | C23: Resina_WTC
A24: 101487 | B24: SOLDADOR DE RESINA MARCA SOLTRONIC (PE015) | C24: Resina_WTC
A25: 101488 | B25: CORTADORA MARCA MAKITA REFERENCIA JS3201 (PE018) | C25: Resina_WTC
A26: 101489 | B26: ENRROLLADORA DE MALLA PARA BOBINAS | C26: B5, N2_WTC
A27: 101490 | B27: PLATAFORMA (PE007) | C27: B5, N1_WTC
A28: 101491 | B28: SUB-ESTACION ELECTRICA DE 13.200 WATS MARCA MTG SE | C28: B5_WTC
A29: 101492 | B29: BOBINADORA PREPARACION MANDRIL TRANSTECNO PE012 | C29: B5, N1_WTC
A30: 101494 | B30: ESTIBADORA AZUL MARCA HU-LIF 3000 KG | C30: Almacén_WTC
A31: 101496 | B31: AUTOCLAVE PLANTA DE IMPREGNACION (PE006) | C31: B5, N1_WTC
B32: MOTOR 5.5HP 1800RPM 112B5 IE3 | C32: B5, N1_WTC
B33: RED. NMRV150 20/1 PAM160B5 | C33: B5, N1_WTC
B34: RETROFITTING MAQUINA IMPREGNACION RESINA | C34: B5, N1_WTC
A35: 101497 | B35: SOLDADOR MARCA MILLER REFERENCIA CST 280 (BN020) | C35: B2, N2_WTC
A36: 101498 | B36: BOBINADORA ALTA TENSION RESINA (PE011) | C36: B1, N1_WTC
A37: 101499 | B37: MALACATE PARA MOLDES 700 KG (PE019) | C37: B5, N2_WTC
A38: 101500 | B38: ESTIBADORA 3 TON AZUL (GN033) | C38: B5_WTC
A39: 101501 | B39: BOMBA DE VACIO SV200 (PE003) | C39: B5, N1_WTC
A40: 101504 | B40: HORNO DE CURADO RESINA PE009 | C40: B5, N2_WTC
A41: 101505 | B41: PUENTE GRUA 1 TONELADA POLIPASTO (PE 014) +ADICION | C41: B2, N2_WTC
A42: 101506 | B42: ADICION AREA RESINA | C42: B5_WTC
...

Sheet Base de datos
P1: Se traslada | R1: Si se traslada. Poner ubicación en WCT
A2: Activo fijo | B2: Subnúmero | C2: Denominación del activo fijo | D2: Capitalizado el | E2: Val.adq. | F2: Amo acum. | G2: Val.cont. | H2: Moneda | I2: Sociedad | J2: Clase activos fijos | K2: Descapitalización el | L2: Centro de costo | M2: Nombre | N2: Centro de beneficio | O2: Seccion | P2: Si | Q2: No | R2: Ubicación en nueva planta. | S2: Observacion
A3: 101464 | B3: 0 | C3: IMPRESORA MULTIFUNCIONAL LEXMARK MX421 | D3: 42005 | E3: 1584000 | F3: -1584000 | G3: 0 | H3: COP | I3: 3009 | J3: CO52001 | L3: 47567015 | M3: Almacén | N3: 41756150 | O3: Almacén_WTC
A4: 101465 | B4: 0 | C4: DOBLADORA HIDRAULICA (EN079) | D4: 42005 | E4: 2890000 | F4: -2551514 | G4: 338486 | H4: COP | I4: 3009 | J4: CO41001 | L4: 47544024 | M4: Ensamble Parte Activa >300 KVA | N4: 41754150 | O4: B1, N2, M2_WTC
A5: 101466 | B5: 0 | C5: ULTRAMAX II 695 PRO AIRLESS | D5: 42005 | E5: 10900000 | F5: -6415573 | G5: 4484427 | H5: COP | I5: 3009 | J5: CO41001 | L5: 47544011 | M5: Preparación e Pintura Soldadura | N5: 41754150 | O5: B4, N1_WTC
A6: 101467 | B6: 0 | C6: CONSOLA DE IMPULSO SERIE HV 2013 - OJO 01728 EQUIP | D6: 42005 | E6: 151751504 | F6: -133977867 | G6: 17773637 | H6: COP | I6: 3009 | J6: CO41001 | L6: 47544032 | M6: Laboratório Aceite, Encapasuldo y Seco >300 kVA | N6: 41754150 | O6: Pruebas_WTC
A7: 101468 | B7: 0 | C7: PUENTE GRUA 20 TONELADAS MARCA HYUNDAI (GN017) | D7: 42005 | E7: 160000000 | F7: -141260274 | G7: 18739726 | H7: COP | I7: 3009 | J7: CO41001 | L7: 47544025 | M7: Encubado | N7: 41754150 | O7: B1, N4_WTC
A8: 101470 | B8: 0 | C8: BASCULA DIGITAL 20 TONELADAS MARCA LEXUS - REF FOX | D8: 42174 | E8: 6284045 | F8: -5417123 | G8: 866922 | H8: COP | I8: 3009 | J8: CO41001 | L8: 47544025 | M8: Encubado | N8: 41754150 | O8: B1, N4_WTC
A9: 101472 | B9: 0 | C9: MONTACARGA DE 3 TONELADAS MARCA NISSAN REF MI05150 | D9: 42702 | E9: 97440000 | F9: -51397004 | G9: 46042996 | H9: COP | I9: 3009 | J9: CO41001 | L9: 47567015 | M9: Almacén | N9: 41756150 | O9: Almacén_WTC
A10: 101478 | B10: 0 | C10: SISTEMA DE AIRE ACONDIONADO MARCA MCQUAY (GN063) | D10: 42736 | E10: 1800000 | F10: -1800000 | G10: 0 | H10: COP | I10: 3009 | J10: CO51001 | L10: 47502031 | M10: Compras | N10: 41750150 | O10: Administracion_WTC | P10: X | R10: Ejemplo bodega 1
A11: 101479 | B11: 0 | C11: EQUIPO DE AIRE ACONDICIONADO MARCA LG INVERTER V - | D11: 42736 | E11: 2098000 | F11: -2098000 | G11: 0 | H11: COP | I11: 3009 | J11: CO51001 | L11: 47567015 | M11: Almacén | N11: 41756150 | O11: Almacén_WTC
A12: 101480 | B12: 0 | C12: SISTEMA DE AIRE ACONDIONADO MARCA MCQUAY (GN862) | D12: 42736 | E12: 4774280 | F12: -4774280 | G12: 0 | H12: COP | I12: 3009 | J12: CO51001 | L12: 47567015 | M12: Almacén | N12: 41756150 | O12: Almacén_WTC
A13: 101481 | B13: 0 | C13: COMPUTADOR MARCA DELL LATITUDE 3591 SERIE 51D99S2 | D13: 42765 | E13: 2610000 | F13: -2610000 | G13: 0 | H13: COP | I13: 3009 | J13: CO52001 | L13: 47567015 | M13: Almacén | N13: 41756150 | O13: Almacén_WTC
A14: 101482 | B14: 0 | C14: ESTIBADORA AZUL MARCA HU-LIF 3000 KG SERIAL 16115 | D14: 42790 | E14: 3029740 | F14: -2359289 | G14: 670451 | H14: COP | I14: 3009 | J14: CO41001 | L14: 47567015 | M14: Almacén | N14: 41756150 | O14: Almacén_WTC
A15: 101483 | B15: 0 | C15: MAQUINA DE CORTE DE NULEO MTM 1CN008 | D15: 42795 | E15: 746574046 | F15: -289126990 | G15: 457447056 | H15: COP | I15: 3009 | J15: CO41001 | L15: 47544015 | M15: Corte Silicio | N15: 41754150 | O15: B1, N1_WTC
A16: 101483 | B16: 1 | C16: RETROFITTING MAQ CORTE NUCLEO MICRO TOOL | D16: 44895 | E16: 37139561 | F16: -7463825 | G16: 29675736 | H16: COP | I16: 3009 | J16: CO41001 | L16: 47544015 | M16: Corte Silicio | N16: 41754150 | O16: B1, N1_WTC
A17: 101483 | B17: 2 | C17: ACTUALIZACION SISTEMA OPERATIVO MTM | D17: 44844 | E17: 25760840 | F17: -6107318 | G17: 19653522 | H17: COP | I17: 3009 | J17: CO41001 | L17: 47544015 | M17: Corte Silicio | N17: 41754150 | O17: B1, N1_WTC
A18: 101484 | B18: 0 | C18: PUENTE GRUA 500 KG | D18: 42815 | E18: 2142000 | F18: -2142000 | G18: 0 | H18: COP | I18: 3009 | J18: CO41001 | L18: 47544018 | M18: Devanados Encapsulados | N18: 41754150 | O18: B5, N2_WTC | S18: Dar de baja
A19: 101485 | B19: 0 | C19: BOBINADORA DE BAJA TENSION DIGMOTOR (PE 010) | D19: 42856 | E19: 230000 | F19: -168456 | G19: 61544 | H19: COP | I19: 3009 | J19: CO42001 | L19: 47544021 | M19: Devanados Seco DT, MF y MDF | N19: 41754150 | O19: B2, N2_WTC
A20: 101486 | B20: 0 | C20: SOLDADOR MARCA SOLTRONIC REF 0292274 | D20: 42856 | E20: 450000 | F20: -329589 | G20: 120411 | H20: COP | I20: 3009 | J20: CO42001 | L20: 47544018 | M20: Devanados Encapsulados | N20: 41754150 | O20: Resina_WTC | S20: Dar de baja
A21: 101487 | B21: 0 | C21: SOLDADOR DE RESINA MARCA SOLTRONIC (PE015) | D21: 42856 | E21: 450000 | F21: -329589 | G21: 120411 | H21: COP | I21: 3009 | J21: CO42001 | L21: 47544018 | M21: Devanados Encapsulados | N21: 41754150 | O21: Resina_WTC | S21: Dar de baja
A22: 101488 | B22: 0 | C22: CORTADORA MARCA MAKITA REFERENCIA JS3201 (PE018) | D22: 42856 | E22: 455000 | F22: -333251 | G22: 121749 | H22: COP | I22: 3009 | J22: CO42001 | L22: 47544018 | M22: Devanados Encapsulados | N22: 41754150 | O22: Resina_WTC | S22: Dar de baja
A23: 101489 | B23: 0 | C23: ENRROLLADORA DE MALLA PARA BOBINAS | D23: 42856 | E23: 844000 | F23: -618163 | G23: 225837 | H23: COP | I23: 3009 | J23: CO41001 | L23: 47544018 | M23: Devanados Encapsulados | N23: 41754150 | O23: B5, N2_WTC
A24: 101490 | B24: 0 | C24: PLATAFORMA (PE007) | D24: 42856 | E24: 1000000 | F24: -732420 | G24: 267580 | H24: COP | I24: 3009 | J24: CO41001 | L24: 47544017 | M24: Preparación Encapsulados | N24: 41754150 | O24: B5, N1_WTC
A25: 101491 | B25: 0 | C25: SUB-ESTACION ELECTRICA DE 13.200 WATS MARCA MTG SE | D25: 42856 | E25: 1055000 | F25: -772703 | G25: 282297 | H25: COP | I25: 3009 | J25: CO41001 | L25: 47544017 | M25: Preparación Encapsulados | N25: 41754150 | O25: B5_WTC
A26: 101492 | B26: 0 | C26: BOBINADORA PREPARACION MANDRIL TRANSTECNO PE012 | D26: 42856 | E26: 1191000 | F26: -872312 | G26: 318688 | H26: COP | I26: 3009 | J26: CO42001 | L26: 47544017 | M26: Preparación Encapsulados | N26: 41754150 | O26: B5, N1_WTC
A27: 101494 | B27: 0 | C27: ESTIBADORA AZUL MARCA HU-LIF 3000 KG | D27: 42856 | E27: 1650000 | F27: -632123 | G27: 1017877 | H27: COP | I27: 3009 | J27: CO41001 | L27: 47567015 | M27: Almacén | N27: 41756150 | O27: Almacén_WTC
A28: 101496 | B28: 0 | C28: AUTOCLAVE PLANTA DE IMPREGNACION (PE006) | D28: 42856 | E28: 2500000 | F28: -957763 | G28: 1542237 | H28: COP | I28: 3009 | J28: CO41001 | L28: 47544018 | M28: Devanados Encapsulados | N28: 41754150 | O28: B5, N1_WTC
A29: 101496 | B29: 1 | C29: RED. NMRV150 20/1 PAM160B5 | D29: 44727 | E29: 3377550 | F29: -654691 | G29: 2722859 | H29: COP | I29: 3009 | J29: CO41001 | L29: 47544018 | M29: Devanados Encapsulados | N29: 41754150 | O29: B5, N1_WTC
A30: 101496 | B30: 2 | C30: MOTOR 5.5HP 1800RPM 112B5 IE3 | D30: 44727 | E30: 1786565 | F30: -346299 | G30: 1440266 | H30: COP | I30: 3009 | J30: CO41001 | L30: 47544018 | M30: Devanados Encapsulados | N30: 41754150 | O30: B5, N1_WTC
A31: 101496 | B31: 4 | C31: RETROFITTING MAQUINA IMPREGNACION RESINA | D31: 45182 | E31: 1277194572 | F31: -335919668 | G31: 941274904 | H31: COP | I31: 3009 | J31: CO41001 | L31: 47544018 | M31: Devanados Encapsulados | N31: 41754150 | O31: B5, N1_WTC
A32: 101497 | B32: 0 | C32: SOLDADOR MARCA MILLER REFERENCIA CST 280 (BN020) | D32: 42856 | E32: 2577000 | F32: -987262 | G32: 1589738 | H32: COP | I32: 3009 | J32: CO42001 | L32: 47544018 | M32: Devanados Encapsulados | N32: 41754150 | O32: B2, N2_WTC
A33: 101498 | B33: 0 | C33: BOBINADORA ALTA TENSION RESINA (PE011) | D33: 42856 | E33: 2800000 | F33: -1072694 | G33: 1727306 | H33: COP | I33: 3009 | J33: CO42001 | L33: 47544015 | M33: Corte Silicio | N33: 41754150 | O33: B1, N1_WTC | S33: Dar de baja
A34: 101499 | B34: 0 | C34: MALACATE PARA MOLDES 700 KG (PE019) | D34: 42856 | E34: 3000000 | F34: -1149315 | G34: 1850685 | H34: COP | I34: 3009 | J34: CO41001 | L34: 47544017 | M34: Preparación Encapsulados | N34: 41754150 | O34: B5, N2_WTC
A35: 101500 | B35: 0 | C35: ESTIBADORA 3 TON AZUL (GN033) | D35: 42856 | E35: 6200000 | F35: -2375251 | G35: 3824749 | H35: COP | I35: 3009 | J35: CO41001 | L35: 47544018 | M35: Devanados Encapsulados | N35: 41754150 | O35: B5_WTC
A36: 101501 | B36: 0 | C36: BOMBA DE VACIO SV200 (PE003) | D36: 42856 | E36: 7500000 | F36: -2873288 | G36: 4626712 | H36: COP | I36: 3009 | J36: CO42001 | L36: 47544018 | M36: Devanados Encapsulados | N36: 41754150 | O36: B5, N1_WTC
A37: 101504 | B37: 0 | C37: HORNO DE CURADO RESINA PE009 | D37: 42856 | E37: 10000000 | F37: -3831051 | G37: 6168949 | H37: COP | I37: 3009 | J37: CO41001 | L37: 47544018 | M37: Devanados Encapsulados | N37: 41754150 | O37: B5, N2_WTC
A38: 101505 | B38: 0 | C38: PUENTE GRUA 1 TONELADA POLIPASTO (PE 014) +ADICION | D38: 42856 | E38: 50467767 | F38: -19334453 | G38: 31133314 | H38: COP | I38: 3009 | J38: CO41001 | L38: 47544018 | M38: Devanados Encapsulados | N38: 41754150 | O38: B2, N2_WTC
A39: 101506 | B39: 0 | C39: ADICION AREA RESINA | D39: 42856 | E39: 378107500 | F39: -289709765 | G39: 88397735 | H39: COP | I39: 3009 | J39: CO41001 | L39: 47544017 | M39: Preparación Encapsulados | N39: 41754150 | O39: B5_WTC
A40: 101507 | B40: 0 | C40: COMPUTADOR MARCA DELL LATITUDE 3490 SERIE 8GJLWS2 | D40: 42947 | E40: 1954775 | F40: -1954775 | G40: 0 | H40: COP | I40: 3009 | J40: CO52001 | L40: 47567015 | M40: Almacén | N40: 41756150 | O40: Almacén_WTC
...
